<!--
  Copyright 2016 The Cartographer Authors

  Licensed under the Apache License, Version 2.0 (the "License");
  you may not use this file except in compliance with the License.
  You may obtain a copy of the License at

       http://www.apache.org/licenses/LICENSE-2.0

  Unless required by applicable law or agreed to in writing, software
  distributed under the License is distributed on an "AS IS" BASIS,
  WITHOUT WARRANTIES OR CONDITIONS OF ANY KIND, either express or implied.
  See the License for the specific language governing permissions and
  limitations under the License.
-->


<robot name="orne-box2_2d">
  
  <material name="gray">
    <color rgba="0.2 0.2 0.2 1" />
  </material>

  <link name="imu_link">
    <inertial>
      <origin rpy="0 0 0" xyz="0.0 0.0 0.0"/>
      <mass value="0.005"/>
      <inertia ixx="0.001" ixy="0.0" ixz="0.0" iyy="0.001" iyz="0.0" izz="0.001"/>
    </inertial>
    <visual>
      <origin rpy="0 0 0" xyz="0 0 0"/>
      <geometry>
        <box size="0.05 0.05 0.05"/>
      </geometry>
      <material name="gray"/>
    </visual>
  </link>

  <link name="hokuyo_link">
    <inertial>
      <origin rpy="0.0 0.0 0.0" xyz="0.0 0.0 0.0"/>
      <mass value="0.2"/>
      <inertia ixx="0.005" ixy="0.0" ixz="0.0" iyy="0.005" iyz="0.0" izz="0.005"/>
    </inertial>
    <visual>
      <origin rpy="0 0 0" xyz="0 0 0"/>
      <geometry>
        <box size="0.05 0.05 0.05"/>
      </geometry>
      <material name="gray"/>
    </visual>
  </link>

  <!--
  <link name="vertical_laser_link">
    <visual>
      <origin xyz="0 0 0" />
      <geometry>
        <cylinder length="0.05" radius="0.03" />
      </geometry>
      <material name="gray" />
    </visual>
  </link>
  -->

  <link name="left_caster_wheel_link">
    <visual>
      <origin rpy="0 0 0" xyz="0 0 0"/>
      <geometry>
        <cylinder length="0.025" radius="0.050"/>
      </geometry>
      <material name="gray"/>
    </visual>
    <collision>
      <origin rpy="0 0 0" xyz="0 0 0"/>
      <geometry>
        <cylinder length="0.025" radius="0.050"/>
      </geometry>
    </collision>
    <inertial>
      <origin xyz="0 0 0"/>
      <mass value="0.2"/>
      <inertia ixx="0.001" ixy="0.0" ixz="0.0" iyy="0.001" iyz="0.0" izz="0.001"/>
    </inertial>
  </link>

  <link name="left_caster_swivel_link">
    <visual>
      <origin rpy="0 0 0" xyz="0 0 0"/>
      <geometry>
        <box size="0.05 0.05 0.01"/>
      </geometry>
      <material name="gray"/>
    </visual>
    <collision>
      <origin rpy="0 0 0" xyz="0 0 0"/>
      <geometry>
        <box size="0.05 0.05 0.01"/>
      </geometry>
    </collision>
    <inertial>
      <origin xyz="0 0 0"/>
      <mass value="0.1"/>
      <inertia ixx="0.001" ixy="0.0" ixz="0.0" iyy="0.001" iyz="0.0" izz="0.001"/>
    </inertial>
  </link>

  <link name="right_caster_wheel_link">
    <visual>
      <origin rpy="0 0 0" xyz="0 0 0"/>
      <geometry>
        <cylinder length="0.025" radius="0.050"/>
      </geometry>
      <material name="gray"/>
    </visual>
    <collision>
      <origin rpy="0 0 0" xyz="0 0 0"/>
      <geometry>
        <cylinder length="0.025" radius="0.050"/>
      </geometry>
    </collision>
    <inertial>
      <origin xyz="0 0 0"/>
      <mass value="0.2"/>
      <inertia ixx="0.001" ixy="0.0" ixz="0.0" iyy="0.001" iyz="0.0" izz="0.001"/>
    </inertial>
  </link>

  <link name="right_caster_swivel_link">
    <visual>
      <origin rpy="0 0 0" xyz="0 0 0"/>
      <geometry>
        <box size="0.05 0.05 0.01"/>
      </geometry>
      <material name="gray"/>
    </visual>
    <collision>
      <origin rpy="0 0 0" xyz="0 0 0"/>
      <geometry>
        <box size="0.05 0.05 0.01"/>
      </geometry>
    </collision>
    <inertial>
      <origin xyz="0 0 0"/>
      <mass value="0.1"/>
      <inertia ixx="0.001" ixy="0.0" ixz="0.0" iyy="0.001" iyz="0.0" izz="0.001"/>
    </inertial>
  </link>

  <link name="wheel_left_link">
    <visual>
      <origin rpy="0 0 0" xyz="0.0 0.0 0.0"/>
      <geometry>
        <cylinder length="0.045" radius="0.152"/>
      </geometry>
      <material name="gray"/>
    </visual>
    <collision>
      <origin rpy="0 0 0" xyz="0.0 0.0 0.0"/>
      <geometry>
        <cylinder length="0.045" radius="0.152"/>
      </geometry>
    </collision>
    <inertial>
      <origin xyz="0 0 0"/>
      <mass value="0.15"/>
      <inertia ixx="0.005" ixy="0.0" ixz="0.0" iyy="0.005" iyz="0.0" izz="0.01"/>
    </inertial>
  </link>

  <link name="wheel_right_link">
    <visual>
      <origin rpy="0 0 0" xyz="0.0 0.0 0.0"/>
      <geometry>
        <cylinder length="0.045" radius="0.152"/>
      </geometry>
      <material name="gray"/>
    </visual>
    <collision>
      <origin rpy="0 0 0" xyz="0.0 0.0 0.0"/>
      <geometry>
        <cylinder length="0.045" radius="0.152"/>
      </geometry>
    </collision>
    <inertial>
      <origin xyz="0 0 0"/>
      <mass value="0.15"/>
      <inertia ixx="0.005" ixy="0.0" ixz="0.0" iyy="0.005" iyz="0.0" izz="0.01"/>
    </inertial>
  </link>

  <link name="base_link" />

  <joint name="hokuyo_link_joint" type="fixed">
    <axis xyz="1 0 0"/>
    <origin rpy="-3.141592653589793 0 0" xyz="0.374295 0 0.2185"/>
    <parent link="base_link"/>
    <child link="hokuyo_link"/>
  </joint>

  <joint name="imu_joint" type="fixed">
    <axis xyz="1 0 0"/>
    <origin rpy="0 0 0" xyz="0.0 0.0 0.0"/> <!--<origin rpy="-3.141592653589793 0 1.5707963267948966" xyz="0.23 0.0 0.270"/> -->
    <parent link="base_link"/>
    <child link="imu_link"/>
  </joint>

  <!-- 
  <joint name="vertical_laser_link_joint" type="fixed">
    <parent link="base_link" />
    <child link="vertical_laser_link" />
    <origin rpy="0 -1.570796 3.141593" xyz="0.1007 0 0.1814" />
  </joint>
  -->

  <joint name="left_caster_wheel_joint" type="continuous">
    <parent link="left_caster_swivel_link"/>
    <child link="left_caster_wheel_link"/>
    <origin rpy="-1.5707963267948966 0 0" xyz="0.03 0.0 -0.065"/>
    <axis xyz="0 0 1"/>
    <limit effort="0.0" lower="-1e15" upper="1e15" velocity="0.0"/>
    <dynamics damping="0.01"/>
  </joint>

  <joint name="left_caster_swivel_joint" type="continuous">
    <parent link="base_link"/>
    <child link="left_caster_swivel_link"/>
    <origin rpy="0 0 0" xyz="0.362 0.150 0.115"/>
    <axis xyz="0 0 1"/>
    <limit effort="0.0" lower="-1e15" upper="1e15" velocity="0.0"/>
    <dynamics damping="0.01"/>
  </joint>

  <joint name="right_caster_wheel_joint" type="continuous">
    <parent link="right_caster_swivel_link"/>
    <child link="right_caster_wheel_link"/>
    <origin rpy="-1.5707963267948966 0 0" xyz="0.03 0.0 -0.065"/>
    <axis xyz="0 0 1"/>
    <limit effort="0.0" lower="-1e15" upper="1e15" velocity="0.0"/>
    <dynamics damping="0.01"/>
  </joint>

  <joint name="right_caster_swivel_joint" type="continuous">
    <parent link="base_link"/>
    <child link="right_caster_swivel_link"/>
    <origin rpy="0 0 0" xyz="0.362 -0.150 0.115"/>
    <axis xyz="0 0 1"/>
    <limit effort="0.0" lower="-1e15" upper="1e15" velocity="0.0"/>
    <dynamics damping="0.01"/>
  </joint>

  <joint name="left_wheel_joint" type="continuous">
    <parent link="base_link"/>
    <child link="wheel_left_link"/>
    <origin rpy="-1.5707963267948966 0 0" xyz="0.0 0.23075 0.152"/>
    <axis xyz="0 0 1"/>
    <limit effort="10.5" lower="-1e15" upper="1e15" velocity="10.0"/>
    <dynamics damping="0.05"/>
  </joint>

  <joint name="right_wheel_joint" type="continuous">
    <parent link="base_link"/>
    <child link="wheel_right_link"/>
    <origin rpy="-1.5707963267948966 0 0" xyz="0.0 -0.23075 0.152"/>
    <axis xyz="0 0 1"/>
    <limit effort="10.5" lower="-1e15" upper="1e15" velocity="10.0"/>
    <dynamics damping="0.05"/>
  </joint>
</robot>
